[2025-06-06T07:41:34.923+0000] {taskinstance.py:1979} INFO - Dependencies all met for dep_context=non-requeueable deps ti=<TaskInstance: LR_duration_prediction_training.train_model manual__2025-06-06T07:41:33.456789+00:00 [queued]>
[2025-06-06T07:41:34.927+0000] {taskinstance.py:1979} INFO - Dependencies all met for dep_context=requeueable deps ti=<TaskInstance: LR_duration_prediction_training.train_model manual__2025-06-06T07:41:33.456789+00:00 [queued]>
[2025-06-06T07:41:34.927+0000] {taskinstance.py:2193} INFO - Starting attempt 1 of 1
[2025-06-06T07:41:34.934+0000] {taskinstance.py:2217} INFO - Executing <Task(PythonOperator): train_model> on 2025-06-06 07:41:33.456789+00:00
[2025-06-06T07:41:34.939+0000] {standard_task_runner.py:60} INFO - Started process 588 to run task
[2025-06-06T07:41:34.941+0000] {standard_task_runner.py:87} INFO - Running: ['***', 'tasks', 'run', 'LR_duration_prediction_training', 'train_model', 'manual__2025-06-06T07:41:33.456789+00:00', '--job-id', '23', '--raw', '--subdir', 'DAGS_FOLDER/LR_duration-prediction_dag.py', '--cfg-path', '/tmp/tmp_rn85y_y']
[2025-06-06T07:41:34.942+0000] {standard_task_runner.py:88} INFO - Job 23: Subtask train_model
[2025-06-06T07:41:34.953+0000] {logging_mixin.py:188} WARNING - /home/***/.local/lib/python3.8/site-packages/***/settings.py:194 DeprecationWarning: The sql_alchemy_conn option in [core] has been moved to the sql_alchemy_conn option in [database] - the old setting has been used, but please update your config.
[2025-06-06T07:41:34.975+0000] {task_command.py:423} INFO - Running <TaskInstance: LR_duration_prediction_training.train_model manual__2025-06-06T07:41:33.456789+00:00 [running]> on host eb1ae944af40
[2025-06-06T07:41:35.028+0000] {taskinstance.py:2513} INFO - Exporting env vars: AIRFLOW_CTX_DAG_OWNER='***' AIRFLOW_CTX_DAG_ID='LR_duration_prediction_training' AIRFLOW_CTX_TASK_ID='train_model' AIRFLOW_CTX_EXECUTION_DATE='2025-06-06T07:41:33.456789+00:00' AIRFLOW_CTX_TRY_NUMBER='1' AIRFLOW_CTX_DAG_RUN_ID='manual__2025-06-06T07:41:33.456789+00:00'
[2025-06-06T07:41:40.465+0000] {taskinstance.py:2731} ERROR - Task failed with exception
Traceback (most recent call last):
  File "/home/airflow/.local/lib/python3.8/site-packages/airflow/models/taskinstance.py", line 444, in _execute_task
    result = _execute_callable(context=context, **execute_callable_kwargs)
  File "/home/airflow/.local/lib/python3.8/site-packages/airflow/models/taskinstance.py", line 414, in _execute_callable
    return execute_callable(context=context, **execute_callable_kwargs)
  File "/home/airflow/.local/lib/python3.8/site-packages/airflow/operators/python.py", line 200, in execute
    return_value = self.execute_callable()
  File "/home/airflow/.local/lib/python3.8/site-packages/airflow/operators/python.py", line 217, in execute_callable
    return self.python_callable(*self.op_args, **self.op_kwargs)
  File "/opt/airflow/dags/LR_duration-prediction_dag.py", line 102, in train_pipeline
    df_train = read_dataframe(year, month)
  File "/opt/airflow/dags/LR_duration-prediction_dag.py", line 36, in read_dataframe
    df = pd.read_parquet(url)
  File "/home/airflow/.local/lib/python3.8/site-packages/pandas/io/parquet.py", line 509, in read_parquet
    return impl.read(
  File "/home/airflow/.local/lib/python3.8/site-packages/pandas/io/parquet.py", line 220, in read
    path_or_handle, handles, kwargs["filesystem"] = _get_path_or_handle(
  File "/home/airflow/.local/lib/python3.8/site-packages/pandas/io/parquet.py", line 110, in _get_path_or_handle
    handles = get_handle(
  File "/home/airflow/.local/lib/python3.8/site-packages/pandas/io/common.py", line 716, in get_handle
    ioargs = _get_filepath_or_buffer(
  File "/home/airflow/.local/lib/python3.8/site-packages/pandas/io/common.py", line 368, in _get_filepath_or_buffer
    with urlopen(req_info) as req:
  File "/home/airflow/.local/lib/python3.8/site-packages/pandas/io/common.py", line 270, in urlopen
    return urllib.request.urlopen(*args, **kwargs)
  File "/usr/local/lib/python3.8/urllib/request.py", line 222, in urlopen
    return opener.open(url, data, timeout)
  File "/usr/local/lib/python3.8/urllib/request.py", line 531, in open
    response = meth(req, response)
  File "/usr/local/lib/python3.8/urllib/request.py", line 640, in http_response
    response = self.parent.error(
  File "/usr/local/lib/python3.8/urllib/request.py", line 569, in error
    return self._call_chain(*args)
  File "/usr/local/lib/python3.8/urllib/request.py", line 502, in _call_chain
    result = func(*args)
  File "/usr/local/lib/python3.8/urllib/request.py", line 649, in http_error_default
    raise HTTPError(req.full_url, code, msg, hdrs, fp)
urllib.error.HTTPError: HTTP Error 403: Forbidden
[2025-06-06T07:41:40.481+0000] {taskinstance.py:1149} INFO - Marking task as FAILED. dag_id=LR_duration_prediction_training, task_id=train_model, execution_date=20250606T074133, start_date=20250606T074134, end_date=20250606T074140
[2025-06-06T07:41:40.491+0000] {standard_task_runner.py:107} ERROR - Failed to execute job 23 for task train_model (HTTP Error 403: Forbidden; 588)
[2025-06-06T07:41:40.509+0000] {local_task_job_runner.py:234} INFO - Task exited with return code 1
[2025-06-06T07:41:40.529+0000] {taskinstance.py:3312} INFO - 0 downstream tasks scheduled from follow-on schedule check
