[2025-06-05T18:29:02.024+0000] {taskinstance.py:1979} INFO - Dependencies all met for dep_context=non-requeueable deps ti=<TaskInstance: duration_prediction_training.train_model manual__2025-06-05T18:28:59.862498+00:00 [queued]>
[2025-06-05T18:29:02.030+0000] {taskinstance.py:1979} INFO - Dependencies all met for dep_context=requeueable deps ti=<TaskInstance: duration_prediction_training.train_model manual__2025-06-05T18:28:59.862498+00:00 [queued]>
[2025-06-05T18:29:02.031+0000] {taskinstance.py:2193} INFO - Starting attempt 1 of 1
[2025-06-05T18:29:02.040+0000] {taskinstance.py:2217} INFO - Executing <Task(PythonOperator): train_model> on 2025-06-05 18:28:59.862498+00:00
[2025-06-05T18:29:02.049+0000] {standard_task_runner.py:60} INFO - Started process 345 to run task
[2025-06-05T18:29:02.052+0000] {standard_task_runner.py:87} INFO - Running: ['***', 'tasks', 'run', 'duration_prediction_training', 'train_model', 'manual__2025-06-05T18:28:59.862498+00:00', '--job-id', '12', '--raw', '--subdir', 'DAGS_FOLDER/duration-prediction_dag.py', '--cfg-path', '/tmp/tmp1l8yhsrh']
[2025-06-05T18:29:02.053+0000] {standard_task_runner.py:88} INFO - Job 12: Subtask train_model
[2025-06-05T18:29:02.067+0000] {logging_mixin.py:188} WARNING - /home/***/.local/lib/python3.8/site-packages/***/settings.py:194 DeprecationWarning: The sql_alchemy_conn option in [core] has been moved to the sql_alchemy_conn option in [database] - the old setting has been used, but please update your config.
[2025-06-05T18:29:02.091+0000] {task_command.py:423} INFO - Running <TaskInstance: duration_prediction_training.train_model manual__2025-06-05T18:28:59.862498+00:00 [running]> on host 61b8c93aba3a
[2025-06-05T18:29:02.163+0000] {taskinstance.py:2513} INFO - Exporting env vars: AIRFLOW_CTX_DAG_OWNER='***' AIRFLOW_CTX_DAG_ID='duration_prediction_training' AIRFLOW_CTX_TASK_ID='train_model' AIRFLOW_CTX_EXECUTION_DATE='2025-06-05T18:28:59.862498+00:00' AIRFLOW_CTX_TRY_NUMBER='1' AIRFLOW_CTX_DAG_RUN_ID='manual__2025-06-05T18:28:59.862498+00:00'
[2025-06-05T18:29:03.096+0000] {logging_mixin.py:188} INFO - Loaded records: 3403766
[2025-06-05T18:29:06.248+0000] {logging_mixin.py:188} INFO - Records after preparation: 3316216
[2025-06-05T18:29:11.181+0000] {taskinstance.py:2483} ERROR - Received SIGTERM. Terminating subprocesses.
[2025-06-05T18:29:11.192+0000] {taskinstance.py:2731} ERROR - Task failed with exception
Traceback (most recent call last):
  File "/home/airflow/.local/lib/python3.8/site-packages/airflow/models/taskinstance.py", line 444, in _execute_task
    result = _execute_callable(context=context, **execute_callable_kwargs)
  File "/home/airflow/.local/lib/python3.8/site-packages/airflow/models/taskinstance.py", line 414, in _execute_callable
    return execute_callable(context=context, **execute_callable_kwargs)
  File "/home/airflow/.local/lib/python3.8/site-packages/airflow/operators/python.py", line 200, in execute
    return_value = self.execute_callable()
  File "/home/airflow/.local/lib/python3.8/site-packages/airflow/operators/python.py", line 217, in execute_callable
    return self.python_callable(*self.op_args, **self.op_kwargs)
  File "/opt/airflow/dags/duration-prediction_dag.py", line 56, in train_pipeline
    for d in dicts_iter:
  File "/opt/airflow/dags/duration-prediction_dag.py", line 53, in <genexpr>
    dicts_iter = (df.iloc[i:i+batch_size][categorical].to_dict(orient='records')
  File "/home/airflow/.local/lib/python3.8/site-packages/pandas/core/frame.py", line 1988, in to_dict
    return to_dict(self, orient, into, index)
  File "/home/airflow/.local/lib/python3.8/site-packages/pandas/core/methods/to_dict.py", line 156, in to_dict
    return [
  File "/home/airflow/.local/lib/python3.8/site-packages/pandas/core/methods/to_dict.py", line 156, in <listcomp>
    return [
  File "/home/airflow/.local/lib/python3.8/site-packages/pandas/core/methods/to_dict.py", line 153, in <genexpr>
    rows = (
  File "/home/airflow/.local/lib/python3.8/site-packages/airflow/models/taskinstance.py", line 2485, in signal_handler
    raise AirflowException("Task received SIGTERM signal")
airflow.exceptions.AirflowException: Task received SIGTERM signal
[2025-06-05T18:29:11.203+0000] {taskinstance.py:1149} INFO - Marking task as FAILED. dag_id=duration_prediction_training, task_id=train_model, execution_date=20250605T182859, start_date=20250605T182902, end_date=20250605T182911
[2025-06-05T18:29:11.212+0000] {standard_task_runner.py:107} ERROR - Failed to execute job 12 for task train_model (Task received SIGTERM signal; 345)
[2025-06-05T18:29:11.331+0000] {local_task_job_runner.py:234} INFO - Task exited with return code 1
[2025-06-05T18:29:11.347+0000] {taskinstance.py:3312} INFO - 0 downstream tasks scheduled from follow-on schedule check
